{
 "cells": [
  {
   "cell_type": "code",
   "execution_count": 2,
   "metadata": {},
   "outputs": [
    {
     "name": "stdout",
     "output_type": "stream",
     "text": [
      "Class names: ['infected', 'notinfected', 'test_data_dir']\n",
      "Number of training samples: 1540\n",
      "Number of testing samples: 386\n"
     ]
    }
   ],
   "source": [
    "import os\n",
    "from sklearn.model_selection import train_test_split\n",
    "\n",
    "# Define the directory containing your dataset\n",
    "data_dir = \"PCOS\"\n",
    "\n",
    "# Get the list of subdirectories (infected and notinfected)\n",
    "class_names = os.listdir(data_dir)\n",
    "print(\"Class names:\", class_names)\n",
    "\n",
    "# Define lists to store file paths and labels\n",
    "file_paths = []\n",
    "labels = []\n",
    "\n",
    "# Iterate through each class directory\n",
    "for class_name in class_names:\n",
    "    class_dir = os.path.join(data_dir, class_name)\n",
    "    # Get the list of image files in the class directory\n",
    "    image_files = [os.path.join(class_dir, file) for file in os.listdir(class_dir)]\n",
    "    # Add the image file paths to the list\n",
    "    file_paths.extend(image_files)\n",
    "    # Add the corresponding label to the labels list\n",
    "    labels.extend([class_name] * len(image_files))\n",
    "\n",
    "# Split the dataset into training and testing sets\n",
    "train_files, test_files, train_labels, test_labels = train_test_split(file_paths, labels, test_size=0.2, random_state=42)\n",
    "\n",
    "print(\"Number of training samples:\", len(train_files))\n",
    "print(\"Number of testing samples:\", len(test_files))\n"
   ]
  },
  {
   "cell_type": "code",
   "execution_count": 3,
   "metadata": {},
   "outputs": [],
   "source": [
    "import tensorflow as tf\n",
    "from tensorflow.keras import layers, models\n"
   ]
  },
  {
   "cell_type": "code",
   "execution_count": 4,
   "metadata": {},
   "outputs": [],
   "source": [
    "img_height = 180\n",
    "img_width = 180\n",
    "batch_size=32"
   ]
  },
  {
   "cell_type": "code",
   "execution_count": 5,
   "metadata": {},
   "outputs": [
    {
     "name": "stderr",
     "output_type": "stream",
     "text": [
      "c:\\Users\\Asus\\AppData\\Local\\Programs\\Python\\Python312\\Lib\\site-packages\\keras\\src\\layers\\convolutional\\base_conv.py:99: UserWarning: Do not pass an `input_shape`/`input_dim` argument to a layer. When using Sequential models, prefer using an `Input(shape)` object as the first layer in the model instead.\n",
      "  super().__init__(\n"
     ]
    }
   ],
   "source": [
    "model = models.Sequential([\n",
    "    layers.Conv2D(32, (3, 3), activation='relu', input_shape=(img_height, img_width, 3)),\n",
    "    layers.MaxPooling2D((2, 2)),\n",
    "    layers.Conv2D(64, (3, 3), activation='relu'),\n",
    "    layers.MaxPooling2D((2, 2)),\n",
    "    layers.Conv2D(64, (3, 3), activation='relu'),\n",
    "    layers.Flatten(),\n",
    "    layers.Dense(64, activation='relu'),\n",
    "    layers.Dense(2)  # 2 output classes: infected or non-infected\n",
    "])\n"
   ]
  },
  {
   "cell_type": "code",
   "execution_count": 6,
   "metadata": {},
   "outputs": [],
   "source": [
    "model.compile(optimizer='adam',\n",
    "              loss=tf.keras.losses.SparseCategoricalCrossentropy(from_logits=True),\n",
    "              metrics=['accuracy'])\n"
   ]
  },
  {
   "cell_type": "code",
   "execution_count": 7,
   "metadata": {},
   "outputs": [
    {
     "name": "stdout",
     "output_type": "stream",
     "text": [
      "Found 1939 files belonging to 3 classes.\n",
      "Using 1552 files for training.\n"
     ]
    }
   ],
   "source": [
    "train_ds = tf.keras.utils.image_dataset_from_directory(\n",
    "  data_dir,\n",
    "  validation_split=0.2,\n",
    "  subset=\"training\",\n",
    "  seed=123,\n",
    "  image_size=(img_height, img_width),\n",
    "  batch_size=batch_size)"
   ]
  },
  {
   "cell_type": "code",
   "execution_count": 8,
   "metadata": {},
   "outputs": [
    {
     "name": "stdout",
     "output_type": "stream",
     "text": [
      "Found 1939 files belonging to 3 classes.\n",
      "Using 387 files for validation.\n"
     ]
    }
   ],
   "source": [
    "val_ds = tf.keras.utils.image_dataset_from_directory(\n",
    "  data_dir,\n",
    "  validation_split=0.2,\n",
    "  subset=\"validation\",\n",
    "  seed=123,\n",
    "  image_size=(img_height, img_width),\n",
    "  batch_size=batch_size)"
   ]
  },
  {
   "cell_type": "code",
   "execution_count": 9,
   "metadata": {},
   "outputs": [
    {
     "name": "stdout",
     "output_type": "stream",
     "text": [
      "Epoch 1/10\n",
      "\u001b[1m 3/49\u001b[0m \u001b[32m━\u001b[0m\u001b[37m━━━━━━━━━━━━━━━━━━━\u001b[0m \u001b[1m6s\u001b[0m 146ms/step - accuracy: 0.4792 - loss: 623.6220"
     ]
    },
    {
     "ename": "InvalidArgumentError",
     "evalue": "Graph execution error:\n\nDetected at node compile_loss/sparse_categorical_crossentropy/SparseSoftmaxCrossEntropyWithLogits/SparseSoftmaxCrossEntropyWithLogits defined at (most recent call last):\n  File \"<frozen runpy>\", line 198, in _run_module_as_main\n\n  File \"<frozen runpy>\", line 88, in _run_code\n\n  File \"C:\\Users\\Asus\\AppData\\Roaming\\Python\\Python312\\site-packages\\ipykernel_launcher.py\", line 18, in <module>\n\n  File \"C:\\Users\\Asus\\AppData\\Roaming\\Python\\Python312\\site-packages\\traitlets\\config\\application.py\", line 1075, in launch_instance\n\n  File \"C:\\Users\\Asus\\AppData\\Roaming\\Python\\Python312\\site-packages\\ipykernel\\kernelapp.py\", line 739, in start\n\n  File \"C:\\Users\\Asus\\AppData\\Roaming\\Python\\Python312\\site-packages\\tornado\\platform\\asyncio.py\", line 205, in start\n\n  File \"c:\\Users\\Asus\\AppData\\Local\\Programs\\Python\\Python312\\Lib\\asyncio\\base_events.py\", line 618, in run_forever\n\n  File \"c:\\Users\\Asus\\AppData\\Local\\Programs\\Python\\Python312\\Lib\\asyncio\\base_events.py\", line 1951, in _run_once\n\n  File \"c:\\Users\\Asus\\AppData\\Local\\Programs\\Python\\Python312\\Lib\\asyncio\\events.py\", line 84, in _run\n\n  File \"C:\\Users\\Asus\\AppData\\Roaming\\Python\\Python312\\site-packages\\ipykernel\\kernelbase.py\", line 545, in dispatch_queue\n\n  File \"C:\\Users\\Asus\\AppData\\Roaming\\Python\\Python312\\site-packages\\ipykernel\\kernelbase.py\", line 534, in process_one\n\n  File \"C:\\Users\\Asus\\AppData\\Roaming\\Python\\Python312\\site-packages\\ipykernel\\kernelbase.py\", line 437, in dispatch_shell\n\n  File \"C:\\Users\\Asus\\AppData\\Roaming\\Python\\Python312\\site-packages\\ipykernel\\ipkernel.py\", line 359, in execute_request\n\n  File \"C:\\Users\\Asus\\AppData\\Roaming\\Python\\Python312\\site-packages\\ipykernel\\kernelbase.py\", line 778, in execute_request\n\n  File \"C:\\Users\\Asus\\AppData\\Roaming\\Python\\Python312\\site-packages\\ipykernel\\ipkernel.py\", line 446, in do_execute\n\n  File \"C:\\Users\\Asus\\AppData\\Roaming\\Python\\Python312\\site-packages\\ipykernel\\zmqshell.py\", line 549, in run_cell\n\n  File \"C:\\Users\\Asus\\AppData\\Roaming\\Python\\Python312\\site-packages\\IPython\\core\\interactiveshell.py\", line 3075, in run_cell\n\n  File \"C:\\Users\\Asus\\AppData\\Roaming\\Python\\Python312\\site-packages\\IPython\\core\\interactiveshell.py\", line 3130, in _run_cell\n\n  File \"C:\\Users\\Asus\\AppData\\Roaming\\Python\\Python312\\site-packages\\IPython\\core\\async_helpers.py\", line 129, in _pseudo_sync_runner\n\n  File \"C:\\Users\\Asus\\AppData\\Roaming\\Python\\Python312\\site-packages\\IPython\\core\\interactiveshell.py\", line 3334, in run_cell_async\n\n  File \"C:\\Users\\Asus\\AppData\\Roaming\\Python\\Python312\\site-packages\\IPython\\core\\interactiveshell.py\", line 3517, in run_ast_nodes\n\n  File \"C:\\Users\\Asus\\AppData\\Roaming\\Python\\Python312\\site-packages\\IPython\\core\\interactiveshell.py\", line 3577, in run_code\n\n  File \"C:\\Users\\Asus\\AppData\\Local\\Temp\\ipykernel_28144\\2136047933.py\", line 1, in <module>\n\n  File \"c:\\Users\\Asus\\AppData\\Local\\Programs\\Python\\Python312\\Lib\\site-packages\\keras\\src\\utils\\traceback_utils.py\", line 118, in error_handler\n\n  File \"c:\\Users\\Asus\\AppData\\Local\\Programs\\Python\\Python312\\Lib\\site-packages\\keras\\src\\backend\\tensorflow\\trainer.py\", line 323, in fit\n\n  File \"c:\\Users\\Asus\\AppData\\Local\\Programs\\Python\\Python312\\Lib\\site-packages\\keras\\src\\backend\\tensorflow\\trainer.py\", line 117, in one_step_on_iterator\n\n  File \"c:\\Users\\Asus\\AppData\\Local\\Programs\\Python\\Python312\\Lib\\site-packages\\keras\\src\\backend\\tensorflow\\trainer.py\", line 105, in one_step_on_data\n\n  File \"c:\\Users\\Asus\\AppData\\Local\\Programs\\Python\\Python312\\Lib\\site-packages\\keras\\src\\backend\\tensorflow\\trainer.py\", line 59, in train_step\n\n  File \"c:\\Users\\Asus\\AppData\\Local\\Programs\\Python\\Python312\\Lib\\site-packages\\keras\\src\\trainers\\trainer.py\", line 321, in compute_loss\n\n  File \"c:\\Users\\Asus\\AppData\\Local\\Programs\\Python\\Python312\\Lib\\site-packages\\keras\\src\\trainers\\compile_utils.py\", line 606, in __call__\n\n  File \"c:\\Users\\Asus\\AppData\\Local\\Programs\\Python\\Python312\\Lib\\site-packages\\keras\\src\\trainers\\compile_utils.py\", line 642, in call\n\n  File \"c:\\Users\\Asus\\AppData\\Local\\Programs\\Python\\Python312\\Lib\\site-packages\\keras\\src\\losses\\loss.py\", line 43, in __call__\n\n  File \"c:\\Users\\Asus\\AppData\\Local\\Programs\\Python\\Python312\\Lib\\site-packages\\keras\\src\\losses\\losses.py\", line 22, in call\n\n  File \"c:\\Users\\Asus\\AppData\\Local\\Programs\\Python\\Python312\\Lib\\site-packages\\keras\\src\\losses\\losses.py\", line 1714, in sparse_categorical_crossentropy\n\n  File \"c:\\Users\\Asus\\AppData\\Local\\Programs\\Python\\Python312\\Lib\\site-packages\\keras\\src\\ops\\nn.py\", line 1541, in sparse_categorical_crossentropy\n\n  File \"c:\\Users\\Asus\\AppData\\Local\\Programs\\Python\\Python312\\Lib\\site-packages\\keras\\src\\backend\\tensorflow\\nn.py\", line 633, in sparse_categorical_crossentropy\n\nReceived a label value of 2 which is outside the valid range of [0, 2).  Label values: 1 0 1 0 0 1 1 1 0 1 0 2 1 1 1 1 1 1 0 0 1 1 1 0 0 1 0 1 1 1 0 0\n\t [[{{node compile_loss/sparse_categorical_crossentropy/SparseSoftmaxCrossEntropyWithLogits/SparseSoftmaxCrossEntropyWithLogits}}]] [Op:__inference_one_step_on_iterator_1859]",
     "output_type": "error",
     "traceback": [
      "\u001b[1;31m---------------------------------------------------------------------------\u001b[0m",
      "\u001b[1;31mInvalidArgumentError\u001b[0m                      Traceback (most recent call last)",
      "Cell \u001b[1;32mIn[9], line 1\u001b[0m\n\u001b[1;32m----> 1\u001b[0m history \u001b[38;5;241m=\u001b[39m \u001b[43mmodel\u001b[49m\u001b[38;5;241;43m.\u001b[39;49m\u001b[43mfit\u001b[49m\u001b[43m(\u001b[49m\u001b[43mtrain_ds\u001b[49m\u001b[43m,\u001b[49m\n\u001b[0;32m      2\u001b[0m \u001b[43m                    \u001b[49m\u001b[43mvalidation_data\u001b[49m\u001b[38;5;241;43m=\u001b[39;49m\u001b[43mval_ds\u001b[49m\u001b[43m,\u001b[49m\n\u001b[0;32m      3\u001b[0m \u001b[43m                    \u001b[49m\u001b[43mepochs\u001b[49m\u001b[38;5;241;43m=\u001b[39;49m\u001b[38;5;241;43m10\u001b[39;49m\u001b[43m,\u001b[49m\n\u001b[0;32m      4\u001b[0m \u001b[43m                    \u001b[49m\u001b[43mbatch_size\u001b[49m\u001b[38;5;241;43m=\u001b[39;49m\u001b[38;5;241;43m32\u001b[39;49m\u001b[43m)\u001b[49m\n",
      "File \u001b[1;32mc:\\Users\\Asus\\AppData\\Local\\Programs\\Python\\Python312\\Lib\\site-packages\\keras\\src\\utils\\traceback_utils.py:123\u001b[0m, in \u001b[0;36mfilter_traceback.<locals>.error_handler\u001b[1;34m(*args, **kwargs)\u001b[0m\n\u001b[0;32m    120\u001b[0m     filtered_tb \u001b[38;5;241m=\u001b[39m _process_traceback_frames(e\u001b[38;5;241m.\u001b[39m__traceback__)\n\u001b[0;32m    121\u001b[0m     \u001b[38;5;66;03m# To get the full stack trace, call:\u001b[39;00m\n\u001b[0;32m    122\u001b[0m     \u001b[38;5;66;03m# `keras.config.disable_traceback_filtering()`\u001b[39;00m\n\u001b[1;32m--> 123\u001b[0m     \u001b[38;5;28;01mraise\u001b[39;00m e\u001b[38;5;241m.\u001b[39mwith_traceback(filtered_tb) \u001b[38;5;28;01mfrom\u001b[39;00m \u001b[38;5;28;01mNone\u001b[39;00m\n\u001b[0;32m    124\u001b[0m \u001b[38;5;28;01mfinally\u001b[39;00m:\n\u001b[0;32m    125\u001b[0m     \u001b[38;5;28;01mdel\u001b[39;00m filtered_tb\n",
      "File \u001b[1;32mc:\\Users\\Asus\\AppData\\Local\\Programs\\Python\\Python312\\Lib\\site-packages\\tensorflow\\python\\eager\\execute.py:53\u001b[0m, in \u001b[0;36mquick_execute\u001b[1;34m(op_name, num_outputs, inputs, attrs, ctx, name)\u001b[0m\n\u001b[0;32m     51\u001b[0m \u001b[38;5;28;01mtry\u001b[39;00m:\n\u001b[0;32m     52\u001b[0m   ctx\u001b[38;5;241m.\u001b[39mensure_initialized()\n\u001b[1;32m---> 53\u001b[0m   tensors \u001b[38;5;241m=\u001b[39m pywrap_tfe\u001b[38;5;241m.\u001b[39mTFE_Py_Execute(ctx\u001b[38;5;241m.\u001b[39m_handle, device_name, op_name,\n\u001b[0;32m     54\u001b[0m                                       inputs, attrs, num_outputs)\n\u001b[0;32m     55\u001b[0m \u001b[38;5;28;01mexcept\u001b[39;00m core\u001b[38;5;241m.\u001b[39m_NotOkStatusException \u001b[38;5;28;01mas\u001b[39;00m e:\n\u001b[0;32m     56\u001b[0m   \u001b[38;5;28;01mif\u001b[39;00m name \u001b[38;5;129;01mis\u001b[39;00m \u001b[38;5;129;01mnot\u001b[39;00m \u001b[38;5;28;01mNone\u001b[39;00m:\n",
      "\u001b[1;31mInvalidArgumentError\u001b[0m: Graph execution error:\n\nDetected at node compile_loss/sparse_categorical_crossentropy/SparseSoftmaxCrossEntropyWithLogits/SparseSoftmaxCrossEntropyWithLogits defined at (most recent call last):\n  File \"<frozen runpy>\", line 198, in _run_module_as_main\n\n  File \"<frozen runpy>\", line 88, in _run_code\n\n  File \"C:\\Users\\Asus\\AppData\\Roaming\\Python\\Python312\\site-packages\\ipykernel_launcher.py\", line 18, in <module>\n\n  File \"C:\\Users\\Asus\\AppData\\Roaming\\Python\\Python312\\site-packages\\traitlets\\config\\application.py\", line 1075, in launch_instance\n\n  File \"C:\\Users\\Asus\\AppData\\Roaming\\Python\\Python312\\site-packages\\ipykernel\\kernelapp.py\", line 739, in start\n\n  File \"C:\\Users\\Asus\\AppData\\Roaming\\Python\\Python312\\site-packages\\tornado\\platform\\asyncio.py\", line 205, in start\n\n  File \"c:\\Users\\Asus\\AppData\\Local\\Programs\\Python\\Python312\\Lib\\asyncio\\base_events.py\", line 618, in run_forever\n\n  File \"c:\\Users\\Asus\\AppData\\Local\\Programs\\Python\\Python312\\Lib\\asyncio\\base_events.py\", line 1951, in _run_once\n\n  File \"c:\\Users\\Asus\\AppData\\Local\\Programs\\Python\\Python312\\Lib\\asyncio\\events.py\", line 84, in _run\n\n  File \"C:\\Users\\Asus\\AppData\\Roaming\\Python\\Python312\\site-packages\\ipykernel\\kernelbase.py\", line 545, in dispatch_queue\n\n  File \"C:\\Users\\Asus\\AppData\\Roaming\\Python\\Python312\\site-packages\\ipykernel\\kernelbase.py\", line 534, in process_one\n\n  File \"C:\\Users\\Asus\\AppData\\Roaming\\Python\\Python312\\site-packages\\ipykernel\\kernelbase.py\", line 437, in dispatch_shell\n\n  File \"C:\\Users\\Asus\\AppData\\Roaming\\Python\\Python312\\site-packages\\ipykernel\\ipkernel.py\", line 359, in execute_request\n\n  File \"C:\\Users\\Asus\\AppData\\Roaming\\Python\\Python312\\site-packages\\ipykernel\\kernelbase.py\", line 778, in execute_request\n\n  File \"C:\\Users\\Asus\\AppData\\Roaming\\Python\\Python312\\site-packages\\ipykernel\\ipkernel.py\", line 446, in do_execute\n\n  File \"C:\\Users\\Asus\\AppData\\Roaming\\Python\\Python312\\site-packages\\ipykernel\\zmqshell.py\", line 549, in run_cell\n\n  File \"C:\\Users\\Asus\\AppData\\Roaming\\Python\\Python312\\site-packages\\IPython\\core\\interactiveshell.py\", line 3075, in run_cell\n\n  File \"C:\\Users\\Asus\\AppData\\Roaming\\Python\\Python312\\site-packages\\IPython\\core\\interactiveshell.py\", line 3130, in _run_cell\n\n  File \"C:\\Users\\Asus\\AppData\\Roaming\\Python\\Python312\\site-packages\\IPython\\core\\async_helpers.py\", line 129, in _pseudo_sync_runner\n\n  File \"C:\\Users\\Asus\\AppData\\Roaming\\Python\\Python312\\site-packages\\IPython\\core\\interactiveshell.py\", line 3334, in run_cell_async\n\n  File \"C:\\Users\\Asus\\AppData\\Roaming\\Python\\Python312\\site-packages\\IPython\\core\\interactiveshell.py\", line 3517, in run_ast_nodes\n\n  File \"C:\\Users\\Asus\\AppData\\Roaming\\Python\\Python312\\site-packages\\IPython\\core\\interactiveshell.py\", line 3577, in run_code\n\n  File \"C:\\Users\\Asus\\AppData\\Local\\Temp\\ipykernel_28144\\2136047933.py\", line 1, in <module>\n\n  File \"c:\\Users\\Asus\\AppData\\Local\\Programs\\Python\\Python312\\Lib\\site-packages\\keras\\src\\utils\\traceback_utils.py\", line 118, in error_handler\n\n  File \"c:\\Users\\Asus\\AppData\\Local\\Programs\\Python\\Python312\\Lib\\site-packages\\keras\\src\\backend\\tensorflow\\trainer.py\", line 323, in fit\n\n  File \"c:\\Users\\Asus\\AppData\\Local\\Programs\\Python\\Python312\\Lib\\site-packages\\keras\\src\\backend\\tensorflow\\trainer.py\", line 117, in one_step_on_iterator\n\n  File \"c:\\Users\\Asus\\AppData\\Local\\Programs\\Python\\Python312\\Lib\\site-packages\\keras\\src\\backend\\tensorflow\\trainer.py\", line 105, in one_step_on_data\n\n  File \"c:\\Users\\Asus\\AppData\\Local\\Programs\\Python\\Python312\\Lib\\site-packages\\keras\\src\\backend\\tensorflow\\trainer.py\", line 59, in train_step\n\n  File \"c:\\Users\\Asus\\AppData\\Local\\Programs\\Python\\Python312\\Lib\\site-packages\\keras\\src\\trainers\\trainer.py\", line 321, in compute_loss\n\n  File \"c:\\Users\\Asus\\AppData\\Local\\Programs\\Python\\Python312\\Lib\\site-packages\\keras\\src\\trainers\\compile_utils.py\", line 606, in __call__\n\n  File \"c:\\Users\\Asus\\AppData\\Local\\Programs\\Python\\Python312\\Lib\\site-packages\\keras\\src\\trainers\\compile_utils.py\", line 642, in call\n\n  File \"c:\\Users\\Asus\\AppData\\Local\\Programs\\Python\\Python312\\Lib\\site-packages\\keras\\src\\losses\\loss.py\", line 43, in __call__\n\n  File \"c:\\Users\\Asus\\AppData\\Local\\Programs\\Python\\Python312\\Lib\\site-packages\\keras\\src\\losses\\losses.py\", line 22, in call\n\n  File \"c:\\Users\\Asus\\AppData\\Local\\Programs\\Python\\Python312\\Lib\\site-packages\\keras\\src\\losses\\losses.py\", line 1714, in sparse_categorical_crossentropy\n\n  File \"c:\\Users\\Asus\\AppData\\Local\\Programs\\Python\\Python312\\Lib\\site-packages\\keras\\src\\ops\\nn.py\", line 1541, in sparse_categorical_crossentropy\n\n  File \"c:\\Users\\Asus\\AppData\\Local\\Programs\\Python\\Python312\\Lib\\site-packages\\keras\\src\\backend\\tensorflow\\nn.py\", line 633, in sparse_categorical_crossentropy\n\nReceived a label value of 2 which is outside the valid range of [0, 2).  Label values: 1 0 1 0 0 1 1 1 0 1 0 2 1 1 1 1 1 1 0 0 1 1 1 0 0 1 0 1 1 1 0 0\n\t [[{{node compile_loss/sparse_categorical_crossentropy/SparseSoftmaxCrossEntropyWithLogits/SparseSoftmaxCrossEntropyWithLogits}}]] [Op:__inference_one_step_on_iterator_1859]"
     ]
    }
   ],
   "source": [
    "history = model.fit(train_ds,\n",
    "                    validation_data=val_ds,\n",
    "                    epochs=10,\n",
    "                    batch_size=32)\n"
   ]
  },
  {
   "cell_type": "code",
   "execution_count": 30,
   "metadata": {},
   "outputs": [
    {
     "name": "stdout",
     "output_type": "stream",
     "text": [
      "Found 15 files belonging to 2 classes.\n"
     ]
    }
   ],
   "source": [
    "import tensorflow as tf\n",
    "\n",
    "# Define the directory path containing your test images\n",
    "test_data_dir = \"PCOS/test_data_dir\"\n",
    "\n",
    "# Define the batch size and image dimensions\n",
    "batch_size = 32\n",
    "img_height = 180\n",
    "img_width = 180\n",
    "\n",
    "# Load the test dataset\n",
    "test_ds = tf.keras.utils.image_dataset_from_directory(\n",
    "    test_data_dir,\n",
    "    image_size=(img_height, img_width),\n",
    "    batch_size=batch_size)\n"
   ]
  },
  {
   "cell_type": "code",
   "execution_count": 31,
   "metadata": {},
   "outputs": [
    {
     "name": "stdout",
     "output_type": "stream",
     "text": [
      "1/1 - 0s - 53ms/step - accuracy: 0.8667 - loss: 2.9097\n",
      "\n",
      "Test accuracy: 0.8666666746139526\n"
     ]
    }
   ],
   "source": [
    "test_loss, test_acc = model.evaluate(test_ds, verbose=2)\n",
    "print('\\nTest accuracy:', test_acc)\n"
   ]
  },
  {
   "cell_type": "code",
   "execution_count": 1,
   "metadata": {},
   "outputs": [
    {
     "ename": "NameError",
     "evalue": "name 'model' is not defined",
     "output_type": "error",
     "traceback": [
      "\u001b[1;31m---------------------------------------------------------------------------\u001b[0m",
      "\u001b[1;31mNameError\u001b[0m                                 Traceback (most recent call last)",
      "Cell \u001b[1;32mIn[1], line 2\u001b[0m\n\u001b[0;32m      1\u001b[0m \u001b[38;5;66;03m# Save the trained model\u001b[39;00m\n\u001b[1;32m----> 2\u001b[0m \u001b[43mmodel\u001b[49m\u001b[38;5;241m.\u001b[39msave(\u001b[38;5;124m'\u001b[39m\u001b[38;5;124mimgCNN.h5\u001b[39m\u001b[38;5;124m'\u001b[39m)\n",
      "\u001b[1;31mNameError\u001b[0m: name 'model' is not defined"
     ]
    }
   ],
   "source": [
    "# Save the trained model\n",
    "model.save('imgCNN.h5')\n"
   ]
  },
  {
   "cell_type": "code",
   "execution_count": null,
   "metadata": {},
   "outputs": [],
   "source": []
  }
 ],
 "metadata": {
  "kernelspec": {
   "display_name": "Python 3",
   "language": "python",
   "name": "python3"
  },
  "language_info": {
   "codemirror_mode": {
    "name": "ipython",
    "version": 3
   },
   "file_extension": ".py",
   "mimetype": "text/x-python",
   "name": "python",
   "nbconvert_exporter": "python",
   "pygments_lexer": "ipython3",
   "version": "3.12.0"
  }
 },
 "nbformat": 4,
 "nbformat_minor": 2
}
